Workbook

Sheet DCL TCERS
A1: Discriminação | B1: Codificação | C1: 42735 | D1: 42855 | E1: 42916
A2: (1) DÍVIDA CONSOLIDADA OU FUNDADA | C2: =SUM(C3:C46,C51:C103,C109:C127)-SUM(C47:C50,C104:C108) -> 0 | D2: =SUM(D3:D46,D51:D103,D109:D127)-SUM(D47:D50,D104:D108) -> 0 | E2: =SUM(E3:E46,E51:E103,E109:E127)-SUM(E47:E50,E104:E108) -> 0
A3: Precatórios de Pessoal – Regime Especial – a partir de 05/05/2000 – Vencidos e não pagos | B3: 2.1.1.1.1.04.02.00.00.00
A4: Precatórios de Pessoal – Regime Ordinário – a partir de 05/05/2000 – Vencidos e não pagos | B4: 2.1.1.1.1.05.02.00.00.00
A5: Precatórios de Benefícios Previdenciários – Regime Especial – a partir de 05/05/2000 – Vencidos e não pagos | B5: 2.1.1.2.1.04.02.00.00.00
A6: Precatórios de Benefícios Previdenciários – Regime Ordinário – a partir de 05/05/2000 – Vencidos e não pagos | B6: 2.1.1.2.1.05.02.00.00.00
A7: Precatórios de Benefícios Assistenciais – Regime Especial – a partir de 05/05/2000 – Vencidos e não pagos | B7: 2.1.1.3.1.03.02.00.00.00
A8: Precatórios de Benefícios Assistenciais – Regime Ordinário – a partir de 05/05/2000 – Vencidos e não pagos | B8: 2.1.1.3.1.04.02.00.00.00
A9: Contribuições ao RGPS – Débito Parcelado | B9: 2.1.1.4.1.01.02.00.00.00
A10: Contribuições ao RGPS – Débito Parcelado | B10: 2.1.1.4.3.01.02.00.00.00
A11: Contribuições Previdenciárias – Débito Parcelado | B11: 2.1.1.4.1.06.00.00.00.00
A12: Contribuições Previdenciárias – Débito Parcelado | B12: 2.1.1.4.3.06.00.00.00.00
A13: Contribuições Previdenciárias – Débito Parcelado | B13: 2.1.1.4.4.06.00.00.00.00
A14: Contribuições Previdenciárias – Débito Parcelado | B14: 2.1.1.4.5.06.00.00.00.00
... A127: Operação de Crédito Contratada pelo Consórcio Público | B127: 8.5.3.6.0.00.00.00.00.00
A129: (2) DEDUÇÕES | C129: =IF(C131<C138,C141,C131-C138+C141) -> 0 | D129: =IF(D131<D138,D141,D131-D138+D141) -> 0 | E129: =IF(E131<E138,E141,E131-E138+E141) -> 0
A131: (3) DISPONIBILIDADE DE CAIXA BRUTA | C131: =SUM(C132:C136) -> 0 | D131: =SUM(D132:D136) -> 0 | E131: =SUM(E132:E136) -> 0
A132: Conta Única | B132: 1.1.1.1.1.02.00.00.00.00
A133: Bancos Conta Movimento – Demais Contas | B133: 1.1.1.1.1.19.00.00.00.00
A134: Rede Bancária – Arrecadação | B134: 1.1.1.1.1.30.00.00.00.00
A135: Aplicações Financeiras de Liquidez Imediata | B135: 1.1.1.1.1.50.00.00.00.00
A136: Caixa e Equivalente de Caixa em Moeda Estrangeira – Consolidação | B136: 1.1.1.2.1.00.00.00.00.00
A138: (4) RESTOS A PAGAR PROCESSADOS | C138: =SUM(C139) -> 0 | D138: =SUM(D139) -> 0 | E138: =SUM(E139) -> 0
A139: Restos a Pagar Processados | B139: 6.3.2.1.0.00.00.00.00.00
A141: (5) DEMAIS HAVERES FINANCEIROS | C141: =SUM(C142:C153,C159:C165,C167:C168,C170,C174:C182)-SUM(C154:C158,C166,C169,C171:C173) -> 0 | D141: =SUM(D142:D153,D159:D165,D167:D168,D170,D174:D182)-SUM(D154:D158,D166,D169,D171:D173) -> 0 | E141: =SUM(E142:E153,E159:E165,E167:E168,E170,E174:E182)-SUM(E154:E158,E166,E169,E171:E173) -> 0
A142: Empréstimos Concedidos | B142: 1.1.2.4.1.01.00.00.00.00
A143: Empréstimos Concedidos | B143: 1.1.2.4.3.01.00.00.00.00
A144: Empréstimos Concedidos | B144: 1.1.2.4.4.01.00.00.00.00
A145: Empréstimos Concedidos | B145: 1.1.2.4.5.01.00.00.00.00
A146: Financiamentos Concedidos | B146: 1.1.2.4.1.02.00.00.00.00
A147: Financiamentos Concedidos | B147: 1.1.2.4.3.02.00.00.00.00
A148: Financiamentos Concedidos | B148: 1.1.2.4.4.02.00.00.00.00
A149: Financiamentos Concedidos | B149: 1.1.2.4.5.02.00.00.00.00
A150: Juros e Encargos sobre Empréstimos e Financiamentos Concedidos a Receber | B150: 1.1.2.4.1.03.00.00.00.00
A151: Juros e Encargos sobre Empréstimos e Financiamentos Concedidos a Receber | B151: 1.1.2.4.3.03.00.00.00.00
A152: Juros e Encargos sobre Empréstimos e Financiamentos Concedidos a Receber | B152: 1.1.2.4.4.03.00.00.00.00
A153: Juros e Encargos sobre Empréstimos e Financiamentos Concedidos a Receber | B153: 1.1.2.4.5.03.00.00.00.00
... A182: Investimentos e Aplicações Temporárias a Longo Prazo – Consolidação | B182: 1.2.1.3.1.00.00.00.00.00
A184: (6) DÍVIDA CONSOLIDADA LÍQUIDA | C184: =C2-C129 -> 0 | D184: =D2-D129 -> 0 | E184: =E2-E129 -> 0
A186: (7) OUTRAS OBRIGAÇÕES NÃO INTEGRANTES DA DÍVIDA CONSOLIDADA LÍQUIDA | C186: =SUM(C187:C236) -> 0 | D186: =SUM(D187:D236) -> 0 | E186: =SUM(E187:E236) -> 0
...

Sheet RREO Anexo 5 - Resultado Nominal
A1: NOME DO MUNICÍPIO
A2: RELATÓRIO RESUMIDO DA EXECUÇÃO ORÇAMENTÁRIA
A3: DEMONSTRATIVO DO RESULTADO NOMINAL
A4: ORÇAMENTOS FISCAL E DA SEGURIDADE SOCIAL
A5: =CONCATENATE(MONTH('DCL TCERS'!E1)/2,"º Bimestre de ",YEAR('DCL TCERS'!E1)) -> 3º Bimestre de 2017
A7: RREO - ANEXO 5 (LRF, art 53, inciso III) | G7: Em Reais
D8: SALDO
A9: DÍVIDA FISCAL LÍQUIDA | B9: =CONCATENATE("Em ",DAY('DCL TCERS'!C1),"/",MONTH('DCL TCERS'!C1),"/",YEAR('DCL TCERS'!C1)) -> Em 31/12/2016 | D9: =CONCATENATE("Em ",DAY('DCL TCERS'!D1),"/",MONTH('DCL TCERS'!D1),"/",YEAR('DCL TCERS'!D1)) -> Em 30/4/2017 | F9: =CONCATENATE("Em ",DAY('DCL TCERS'!E1),"/",MONTH('DCL TCERS'!E1),"/",YEAR('DCL TCERS'!E1)) -> Em 30/6/2017
B10: (a) | D10: (b) | F10: (c)
A11: DÍVIDA CONSOLIDADA (I) | B11: ='DCL TCERS'!C2 -> 0 | D11: ='DCL TCERS'!D2 -> 0 | F11: ='DCL TCERS'!E2 -> 0
A12: DEDUÇÕES (II) | B12: ='DCL TCERS'!C129 -> 0 | D12: ='DCL TCERS'!D129 -> 0 | F12: ='DCL TCERS'!E129 -> 0
A13: Disponibilidade de Caixa | B13: =IF(B14<B15,0,B14-B15) -> 0 | D13: =IF(D14<D15,0,D14-D15) -> 0 | F13: =IF(F14<F15,0,F14-F15) -> 0
A14: Disponibilidade de Caixa Bruta | B14: ='DCL TCERS'!C131 -> 0 | D14: ='DCL TCERS'!D131 -> 0 | F14: ='DCL TCERS'!E131 -> 0
A15: (-) Restos a Pagar Processados (Exceto precatórios) | B15: ='DCL TCERS'!C138 -> 0 | D15: ='DCL TCERS'!D138 -> 0 | F15: ='DCL TCERS'!E138 -> 0
A16: Demais Haveres Financeiros | B16: ='DCL TCERS'!C141 -> 0 | D16: ='DCL TCERS'!D141 -> 0 | F16: ='DCL TCERS'!E141 -> 0
A17: DÍVIDA CONSOLIDADA LÍQUIDA (III) = (I - II) | B17: =IF(B12>B11,0,B11-B12) -> 0 | D17: =IF(D12>D11,0,D11-D12) -> 0 | F17: =IF(F12>F11,0,F11-F12) -> 0
A18: RECEITA DE PRIVATIZAÇÕES (IV)
A19: PASSIVOS RECONHECIDOS (V)
A20: DÍVIDA FISCAL LÍQUIDA (VI) = (III + IV - V) | B20: =B17+B18-B19 -> 0 | D20: =D17+D18-D19 -> 0 | F20: =F17+F18-F19 -> 0
D22: PERÍODO DE REFERÊNCIA
A23: RESULTADO NOMINAL | C23: No Bimestre | F23: Até o Bimestre
C24: (VIc -VIb) | F24: (VIc - VIa)
A25: VALOR | B25: =F20-D20 -> 0 | E25: =F20-B20 -> 0
A27: DISCRIMINAÇÃO DA META FISCAL | E27: VALOR CORRENTE
A29: META DE RESULTADO NOMINAL FIXADA NO ANEXO DE METAS FISCAIS DA LDO P/ O EXERCÍCIO DE REFERÊNCIA | E29: 0
